Workbook

Sheet CLOTURATION CAISSE
A1: DÉPENCES CAISSE | E1: DIFFERENCES | M1: ETAT DIFFERENCES
A4: DATE | B4: DESIGNATION | C4: MONTANT | E4: Date | F4: Utilisateur | G4: Montant Réel | H4: Montant Virtuelle | I4: Différence | J4: Net | K4: Remarques | M4: Utilisateur | N4: Montant Total
A14: Total | C14: =SUM(C5:C12) -> 0
E45: Total | J45: =SUM(J5:J43) -> 0

Sheet CAISSE-COFFRE
A1: MOUVEMENT CAISSE | K1: MOUVEMENT COFFRE
A4: DATE | B4: Caisse CV | C4: Caisse C | D4: TPE | E4: Dépenses | F4: Remboursement | G4: Convention Mutuelle | H4: Sous-Traitants | I4: Total | K4: Coffre Net Réel | O4: SORTIES COFFRE
A5: 46023 | I5: =SUM(Table_1[[#This Row],[Caisse CV]:[Sous-Traitants]]) -> 0 | K5: =B37+C37+'SOUS-TRAITANTS & CONVENTIONS'!C21+'SOUS-TRAITANTS & CONVENTIONS'!C29+SUM(L30:L31)+L54-Q85 -> 0
A6: 46024 | O6: Date | P6: Désignation | Q6: Montant
A7: 46025
A8: 46026 | K8: Chiffre d'affaire LAM
A9: 46027 | K9: =B37+D37+E37 -> 0
A10: 46028
A11: 46029
A12: 46030 | K12: Chiffre d'affaire Convention
A13: 46031 | K13: =C37+G37 -> 0
A14: 46032
A15: 46033
A16: 46034 | K16: Chiffre d'affaire ST
A17: 46035 | K17: =H37 -> 0
A18: 46036
A19: 46037
A20: 46038 | K20: Chiffre d'Affaire Entrées Supplumentaires
A21: 46039 | K21: =L38 -> 0
A22: 46040
A23: 46041
A24: 46042 | K24: Chiffre D'affaire Globale
A25: 46043 | K25: =K9+K13+K17+K21 -> 0
A26: 46044
A27: 46045
A28: 46046 | K28: ENTRÉES SUPPLUMENTAIRES
A29: 46047 | K29: Date | L29: Montant | M29: Détail
A30: 46048
A31: 46049
A32: 46050
A33: 46051
A34: 46052
A35: 46053
A37: Total | B37: =SUM('CAISSE-COFFRE'!$B$5:$B$35) -> 0 | C37: =SUM(Table_1[Caisse C]) -> 0 | D37: =SUM('CAISSE-COFFRE'!$D$5:$D$35) -> 0 | E37: =SUM('CAISSE-COFFRE'!$E$5:$E$35) -> 0 | F37: =SUM('CAISSE-COFFRE'!$F$5:$F$35) -> 0 | G37: =SUM('CAISSE-COFFRE'!$F$5:$F$35) -> 0 | H37: =SUM('CAISSE-COFFRE'!$F$5:$F$35) -> 0 | I37: =SUM('CAISSE-COFFRE'!$I$5:$I$35) -> 0
A38: Min (-Ven) | B38: =+MIN(B5:B8,B10:B15,B17:B22,B24:B29,B31:B35) -> 0 | D38: =+MIN(D5:D8,D10:D15,D17:D22,D24:D29,D31:D35) -> 0 | E38: =+MIN(E5:E8,E10:E15,E17:E22,E24:E29,E31:E35) -> 0 | F38: =+MIN(F5:F8,F10:F15,F17:F22,F24:F29,F31:F35) -> 0 | H38: =+MIN(H5:H8,H10:H15,H17:H22,H24:H29,H31:H35) -> 0 | I38: =+MIN(I5:I8,I10:I15,I17:I22,I24:I29,I31:I35) -> 0 | K38: TOTAL | L38: =SUM(L30:L36) -> 0
A39: Max (-Ven) | B39: =MAX(B5:B8,B10:B15,B17:B22,B24:B29,B31:B35) -> 0 | D39: =MAX(D5:D8,D10:D15,D17:D22,D24:D29,D31:D35) -> 0 | E39: =MAX(E5:E8,E10:E15,E17:E22,E24:E29,E31:E35) -> 0 | F39: =MAX(F5:F8,F10:F15,F17:F22,F24:F29,F31:F35) -> 0 | H39: =MAX(H5:H8,H10:H15,H17:H22,H24:H29,H31:H35) -> 0 | I39: =MAX(I5:I8,I10:I15,I17:I22,I24:I29,I31:I35) -> 0
A40: MOYENNE (-Ven) | B40: =AVERAGE(B5:B8,B10:B15,B17:B22,B24:B29,B31:B35) -> #DIV/0! | D40: =AVERAGE(D5:D8,D10:D15,D17:D22,D24:D29,D31:D35) -> #DIV/0! | E40: =AVERAGE(E5:E8,E10:E15,E17:E22,E24:E29,E31:E35) -> #DIV/0! | F40: =AVERAGE(F5:F8,F10:F15,F17:F22,F24:F29,F31:F35) -> #DIV/0! | H40: =AVERAGE(H5:H8,H10:H15,H17:H22,H24:H29,H31:H35) -> #DIV/0! | I40: =AVERAGE(I5:I8,I10:I15,I17:I22,I24:I29,I31:I35) -> 0
K43: MOUVEMENT PROFITABILITÉ
K44: DATE | L44: MONTANT | M44: DÉTAIL
K54: TOTAL | L54: =+SUM(L45:L52) -> 0
...

Sheet FOURNISSEURS
A1: FOURNISSEUR LAM | B1: TOTAL DES COMMANDES | C1: PAYER | D1: RESTE
D2: =+Table_2[[#This Row],[TOTAL DES COMMANDES ]]-Table_2[[#This Row],[PAYER ]] -> 0
D3: =+Table_2[[#This Row],[TOTAL DES COMMANDES ]]-Table_2[[#This Row],[PAYER ]] -> 0
D4: =+Table_2[[#This Row],[TOTAL DES COMMANDES ]]-Table_2[[#This Row],[PAYER ]] -> 0
D5: =+Table_2[[#This Row],[TOTAL DES COMMANDES ]]-Table_2[[#This Row],[PAYER ]] -> 0
D6: =+Table_2[[#This Row],[TOTAL DES COMMANDES ]]-Table_2[[#This Row],[PAYER ]] -> 0
D7: =+Table_2[[#This Row],[TOTAL DES COMMANDES ]]-Table_2[[#This Row],[PAYER ]] -> 0
D8: =+Table_2[[#This Row],[TOTAL DES COMMANDES ]]-Table_2[[#This Row],[PAYER ]] -> 0
D9: =+Table_2[[#This Row],[TOTAL DES COMMANDES ]]-Table_2[[#This Row],[PAYER ]] -> 0
D10: =+Table_2[[#This Row],[TOTAL DES COMMANDES ]]-Table_2[[#This Row],[PAYER ]] -> 0
D11: =+Table_2[[#This Row],[TOTAL DES COMMANDES ]]-Table_2[[#This Row],[PAYER ]] -> 0
D12: =+Table_2[[#This Row],[TOTAL DES COMMANDES ]]-Table_2[[#This Row],[PAYER ]] -> 0
D13: =+Table_2[[#This Row],[TOTAL DES COMMANDES ]]-Table_2[[#This Row],[PAYER ]] -> 0
... D38: =+Table_2[[#This Row],[TOTAL DES COMMANDES ]]-Table_2[[#This Row],[PAYER ]] -> 0
A40: TOTAL | B40: =SUM(B2:B38) -> 0 | C40: =SUM(C2:C38) -> 0 | D40: =SUM(D2:D38) -> 0
A43: PAIE ESTIMATION | B43: 0
A44: DEPENSES INTERNE | B44: ='CAISSE-COFFRE'!E37 -> 0
A46: FOURNISSEURS + DEPENCES + PAIE | B46: =B40+B44+B43 -> 0
A49: CA LAM | B49: ='CAISSE-COFFRE'!K9 -> 0
A50: CA C | B50: ='CAISSE-COFFRE'!C37+'CAISSE-COFFRE'!G37 -> 0
A51: CA ST | B51: ='SOUS-TRAITANTS & CONVENTIONS'!B21 -> 0
A52: ENTREES SUPP | B52: ='CAISSE-COFFRE'!L38 -> 0
A53: Chiffre d'Affaire | B53: =B49+B50+B51+B52 -> 0
A55: Profitabilité (CA+ST)-(FR+DEP+ PAIE) | B55: =B53-B46 -> 0
A56: % Profitabilité / Chiffre d'Affaire | B56: =B55/B53 -> #DIV/0!

Sheet SOUS-TRAITANTS & CONVENTIONS
A1: SOUS-TRAITANTS | B1: MONTANT | C1: VERSEMENT | D1: DATE DE RECEPTION | E1: MODE PAIEMENT | F1: RESTE | G1: RESTE MOIS PRECEDANTS | H1: RESTE TOTAL | I1: REMARQUES
A21: Total | B21: =SUM(B2:B19) -> 0 | C21: =SUM(C2:C19) -> 0 | F21: =SUM(F2:F19) -> 0 | G21: =SUM(G2:G19) -> 0 | H21: =SUM(H2:H19) -> 0
A24: CONVENTION | B24: MONTANT | C24: VERSEMENT | D24: DATE DE RECEPTION | E24: MODE PAIEMENT | F24: RESTE | G24: RESTE MOIS PRECEDANTS | H24: RESTE TOTAL | I24: REMARQUES
A29: Total | B29: =SUM(B25:B27) -> 0 | C29: =SUM(C25:C27) -> 0 | F29: =SUM(F25:F27) -> 0 | G29: =SUM(G25:G27) -> 0 | H29: =SUM(H25:H27) -> 0

Sheet PRESENCE
C1: Etats
C2: P | D2: PRESENT(E) | I2: REC | J2: RECUPERATION | O2: P+ | P2: PRESENCE EN + / HS | V2: Non Considéré
C3: G | D3: GARDE NUIT | I3: GV-J | J3: GARDE VENDREDI - JOUR | O3: C.M | P3: Conger Maladie
C4: ABS | D4: ABSENCE | I4: GV-N | J4: GARDE VENDREDI - NUIT | O4: C | P4: Conger
D7: Nouvel An 2026 | O7: Yennayer
A8: N° | B8: Employer | C8: JOUR | D8: 46023 | E8: 46024 | F8: 46025 | G8: 46026 | H8: 46027 | I8: 46028 | J8: 46029 | K8: 46030 | L8: 46031 | M8: 46032 | N8: 46033 | O8: 46034 | P8: 46035 | Q8: 46036 | R8: 46037 | S8: 46038 | T8: 46039 | U8: 46040 | V8: 46041 | W8: 46042 | X8: 46043 | Y8: 46044 | Z8: 46045 | AA8: 46046 | AB8: 46047 | AC8: 46048 | AD8: 46049 | AE8: 46050 | AF8: 46051 | AG8: 46052 | AH8: 46053 | AI8: Remarques
D9: Jeudi | E9: Vendredi | F9: Samedi | G9: Dimanche | H9: Lundi | I9: Mardi | J9: Mercredi | K9: Jeudi | L9: Vendredi | M9: Samedi | N9: Dimanche | O9: Lundi | P9: Mardi | Q9: Mercredi | R9: Jeudi | S9: Vendredi | T9: Samedi | U9: Dimanche | V9: Lundi | W9: Mardi | X9: Mercredi | Y9: Jeudi | Z9: Vendredi | AA9: Samedi | AB9: Dimanche | AC9: Lundi | AD9: Mardi | AE9: Mercredi | AF9: Jeudi | AG9: Vendredi | AH9: Samedi
C10: JOUR
C11: GARDE
C12: JOUR
C13: GARDE
C14: JOUR
C15: GARDE
C16: JOUR
C17: GARDE
C18: JOUR
C19: GARDE
C20: JOUR
C21: GARDE
... C57: GARDE

Sheet RAPPORT DE SALAIRE
G1: 2 000,00 | H1: 1 500,00 | I1: 2 500,00
A2: N° | B2: Personne | C2: Poste | D2: Salaire Net | E2: Présence en + / HS | F2: Déplacement LAM | G2: Garde Nuit | H2: Garde Vendredi - Jour | I2: Garde Vendredi - Nuit | J2: Absence | K2: Prime | L2: Congé | M2: Pénalités | N2: Avances | P2: Salaire | Q2: REMARQUE
P4: =SUM(Table_4[[#This Row],[Column4]:[Colonne1]]) -> 0
P5: =SUM(Table_4[[#This Row],[Column4]:[Colonne1]]) -> 0
P6: =SUM(Table_4[[#This Row],[Column4]:[Colonne1]]) -> 0
P7: =SUM(Table_4[[#This Row],[Column4]:[Colonne1]]) -> 0
P8: =SUM(Table_4[[#This Row],[Column4]:[Colonne1]]) -> 0
P9: =SUM(Table_4[[#This Row],[Column4]:[Colonne1]]) -> 0
P10: =SUM(Table_4[[#This Row],[Column4]:[Colonne1]]) -> 0
P11: =SUM(Table_4[[#This Row],[Column4]:[Colonne1]]) -> 0
P12: =SUM(Table_4[[#This Row],[Column4]:[Colonne1]]) -> 0
P13: =SUM(Table_4[[#This Row],[Column4]:[Colonne1]]) -> 0
P14: =SUM(Table_4[[#This Row],[Column4]:[Colonne1]]) -> 0
P15: =SUM(Table_4[[#This Row],[Column4]:[Colonne1]]) -> 0
... P27: =SUM(Table_4[[#This Row],[Column4]:[Colonne1]]) -> 0
P28: Total | Q28: =+SUM(P4:P27) -> 0
O111: ,

Sheet Feuil1
